Workbook

Sheet concept
A1: concept_id | B1: retired | C1: retired_by | D1: datatype_id | E1: class_id | F1: is_set | G1: creator | H1: date_created | I1: changed_by | J1: date_changed | K1: uuid
A2: 1 | B2: 0 | D2: 4 | E2: 11 | F2: 0 | G2: 1 | H2: 38358 | I2: 1 | J2: 41466.191 | K2: 31b2810e-0370-102d-b0e3-001ec94a0cc1
A3: 2 | B3: 0 | D3: 4 | E3: 11 | F3: 0 | G3: 1 | H3: 38908.645 | I3: 1 | J3: 44811.154 | K3: 31b4a16e-0370-102d-b0e3-001ec94a0cc1
A4: 3 | B4: 0 | D4: 4 | E4: 16 | F4: 0 | G4: 1 | H4: 39389.421 | I4: 1 | J4: 42986.008 | K4: 31bd79ec-0370-102d-b0e3-001ec94a0cc1
A5: 4 | B5: 0 | D5: 4 | E5: 17 | F5: 0 | G5: 1 | H5: 39657.614 | I5: 1 | J5: 41466.191 | K5: 31c2c5fa-0370-102d-b0e3-001ec94a0cc1
A6: 5 | B6: 0 | D6: 4 | E6: 11 | F6: 0 | G6: 1 | H6: 38364 | I6: 1 | J6: 42552.541 | K6: 31b2a94a-0370-102d-b0e3-001ec94a0cc1
A7: 6 | B7: 0 | D7: 4 | E7: 18 | F7: 0 | G7: 1 | H7: 39657.612 | I7: 1 | J7: 41466.191 | K7: 31c1d492-0370-102d-b0e3-001ec94a0cc1
A8: 7 | B8: 0 | D8: 4 | E8: 18 | F8: 0 | G8: 1 | H8: 39657.613 | I8: 1 | J8: 41466.191 | K8: 31c1d564-0370-102d-b0e3-001ec94a0cc1
A9: 8 | B9: 0 | D9: 4 | E9: 18 | F9: 0 | G9: 1 | H9: 39657.613 | I9: 1 | J9: 41466.191 | K9: 31c1d640-0370-102d-b0e3-001ec94a0cc1
A10: 9 | B10: 0 | D10: 4 | E10: 11 | F10: 0 | G10: 1 | H10: 38981.509 | I10: 1 | J10: 41300.442 | K10: 31b66f1c-0370-102d-b0e3-001ec94a0cc1
A11: 10 | B11: 0 | D11: 4 | E11: 11 | F11: 0 | G11: 1 | H11: 38358 | I11: 1 | J11: 42988.661 | K11: 31b2803c-0370-102d-b0e3-001ec94a0cc1
A12: 11 | B12: 0 | D12: 4 | E12: 11 | F12: 0 | G12: 1 | H12: 38358 | I12: 1 | J12: 42982.696 | K12: 31b27f6a-0370-102d-b0e3-001ec94a0cc1
A13: 12 | B13: 0 | D13: 2 | E13: 5 | F13: 0 | G13: 1 | H13: 39625.66 | I13: 1 | J13: 41466.191 | K13: 31c095fa-0370-102d-b0e3-001ec94a0cc1
... A24: 23 | B24: 0 | D24: 4 | E24: 18 | F24: 0 | G24: 1 | H24: 39017.488 | I24: 1 | J24: 44811.156 | K24: 31b6b986-0370-102d-b0e3-001ec94a0cc1
A25: 24 | B25: 1 | C25: 1 | D25: 4 | E25: 18 | F25: 0 | G25: 1 | H25: 39657.615 | I25: 1 | J25: 42530.533 | K25: 31c2c6ea-0370-102d-b0e3-001ec94a0cc1
A26: 25 | B26: 0 | D26: 4 | E26: 18 | F26: 0 | G26: 1 | H26: 39017.486 | I26: 1 | J26: 42530.508 | K26: 31b6b7d8-0370-102d-b0e3-001ec94a0cc1
A27: 26 | B27: 0 | D27: 4 | E27: 18 | F27: 0 | G27: 1 | H27: 39017.489 | I27: 1 | J27: 42530.484 | K27: 31b6bb34-0370-102d-b0e3-001ec94a0cc1
A28: 27 | B28: 0 | D28: 4 | E28: 5 | F28: 0 | G28: 1 | H28: 38111 | I28: 1 | J28: 44811.157 | K28: 31b0e4ac-0370-102d-b0e3-001ec94a0cc1
A29: 28 | B29: 0 | D29: 4 | E29: 18 | F29: 0 | G29: 1 | H29: 38987.919 | I29: 1 | J29: 44811.157 | K29: 31b69906-0370-102d-b0e3-001ec94a0cc1
A30: 29 | B30: 0 | D30: 4 | E30: 18 | F30: 0 | G30: 1 | H30: 38211 | I30: 1 | J30: 42627.721 | K30: 31c7bbdc-0370-102d-b0e3-001ec94a0cc1
A31: 30 | B31: 0 | D31: 2 | E31: 17 | F31: 1 | G31: 1 | H31: 39657.616 | I31: 1 | J31: 44812.097 | K31: 31c2c834-0370-102d-b0e3-001ec94a0cc1
A32: 31 | B32: 1 | C32: 1 | D32: 4 | E32: 18 | F32: 0 | G32: 1 | H32: 40770.472 | I32: 1 | J32: 41466.191 | K32: 8d86d020-56b2-4b21-9612-38ef59eebafe
A33: 32 | B33: 0 | D33: 4 | E33: 11 | F33: 0 | G33: 1 | H33: 39657.631 | I33: 1 | J33: 41466.191 | K33: 31c2d4be-0370-102d-b0e3-001ec94a0cc1
A34: 33 | B34: 0 | D34: 4 | E34: 11 | F34: 0 | G34: 1 | H34: 39657.631 | I34: 1 | J34: 41466.191 | K34: 31c2d3ec-0370-102d-b0e3-001ec94a0cc1
A35: 34 | B35: 0 | D35: 2 | E35: 11 | F35: 0 | G35: 1 | H35: 39657.632 | I35: 1 | J35: 44812.1 | K35: 31c2d590-0370-102d-b0e3-001ec94a0cc1
A36: 35 | B36: 0 | D36: 4 | E36: 17 | F36: 0 | G36: 1 | H36: 39657.612 | I36: 1 | J36: 41466.191 | K36: 31c1d3c0-0370-102d-b0e3-001ec94a0cc1
A37: 36 | B37: 0 | D37: 4 | E37: 18 | F37: 0 | G37: 1 | H37: 39657.61 | I37: 1 | J37: 41466.191 | K37: 31c1d212-0370-102d-b0e3-001ec94a0cc1
A38: 37 | B38: 0 | D38: 4 | E38: 18 | F38: 0 | G38: 1 | H38: 39657.611 | I38: 1 | J38: 41466.191 | K38: 31c1d2e4-0370-102d-b0e3-001ec94a0cc1
A39: 38 | B39: 0 | D39: 4 | E39: 18 | F39: 0 | G39: 1 | H39: 39657.61 | I39: 1 | J39: 41466.191 | K39: 31c1d140-0370-102d-b0e3-001ec94a0cc1
A40: 39 | B40: 0 | D40: 4 | E40: 4 | F40: 0 | G40: 1 | H40: 37987 | I40: 1 | J40: 41466.191 | K40: 31acf054-0370-102d-b0e3-001ec94a0cc1
A41: 40 | B41: 0 | D41: 4 | E41: 3 | F41: 0 | G41: 1 | H41: 38971.657 | I41: 1 | J41: 41300.442 | K41: 31b64c6c-0370-102d-b0e3-001ec94a0cc1
A42: 41 | B42: 0 | D42: 4 | E42: 3 | F42: 0 | G42: 1 | H42: 38211 | I42: 1 | J42: 42611.033 | K42: 31caeaa0-0370-102d-b0e3-001ec94a0cc1
A43: 42 | B43: 0 | D43: 4 | E43: 3 | F43: 0 | G43: 1 | H43: 38909.427 | I43: 1 | J43: 44811.157 | K43: 31b4a740-0370-102d-b0e3-001ec94a0cc1
A44: 43 | B44: 0 | D44: 1 | E44: 11 | F44: 0 | G44: 1 | H44: 39555.534 | I44: 1 | J44: 41300.442 | K44: 31bf136a-0370-102d-b0e3-001ec94a0cc1
... A254: 253 | B254: 0 | D254: 3 | E254: 7 | F254: 0 | G254: 1 | H254: 41204.601 | I254: 1 | J254: 41248.467 | K254: b63284f8-751d-45b6-b841-a196d6820db0
A255: 254 | B255: 0 | D255: 4 | E255: 10 | F255: 1 | G255: 1 | H255: 41204.601 | K255: e67f950d-172f-400c-a767-e751272183a6
A256: 255 | B256: 0 | D256: 2 | E256: 7 | F256: 0 | G256: 1 | H256: 41204.602 | I256: 1 | J256: 42589.947 | K256: ddf6e09c-f018-4048-a69f-436ff22308b5
A257: 256 | B257: 0 | D257: 4 | E257: 8 | F257: 1 | G257: 1 | H257: 41204.602 | I257: 1 | J257: 41204.604 | K257: 0737cfba-5ae8-4605-bd52-74c26ee4da9e
A258: 257 | B258: 0 | D258: 3 | E258: 7 | F258: 0 | G258: 1 | H258: 41204.603 | I258: 1 | J258: 41248.468 | K258: fdca2fd7-b29a-4969-82b0-8c235c136cf4
A259: 258 | B259: 0 | D259: 3 | E259: 7 | F259: 0 | G259: 1 | H259: 41204.603 | I259: 1 | J259: 41248.468 | K259: 2b952ed6-4c8c-4dc0-889e-2d22c8eb6afc
...

Sheet concept_source
A1: concept_source_id | B1: name | C1: description | D1: hl7_code | E1: creator | F1: date_created | G1: retired | H1: retired_by | I1: date_retired | J1: retire_reason | K1: uuid
A2: 1 | B2: ETB-Tajikistan | C2: Concepts used for ETB Tajikistan created originally by Ali Habib | D2: AT101 | E2: 1 | F2: 40850.78 | G2: 0 | K2: 0c959f37-1c76-41ee-af79-2591577ffd24
A3: 2 | B3: org.openmrs.module.mdrtb | C3: The required concepts for the MDR-TB module | E3: 1 | F3: 40527.584 | G3: 0 | K3: ddb6b595-0b85-4a80-9243-efe4ba404eef
A4: 3 | B4: ZL/PIH installation in Haiti | C4: ZL/ PIH program in Haiti, Created by Ellen Ball | D4: HAITI | E4: 1 | F4: 40773.667 | G4: 0 | K4: 6f449877-943e-457a-bfa4-da3825d2266e
A5: 4 | B5: PIH | C5: Equivalent concept ID in Master Partners-in-Health Concept dictionary | E5: 1 | F5: 40393.077 | G5: 0 | K5: d03f40f6-74f9-11ee-af2b-e86a64440f18

Sheet concept_map
A1: concept_map_id | B1: source_id | C1: source | D1: source_code | E1: comment | F1: creator | G1: date_created | H1: concept_id | I1: uuid
A2: 1 | B2: 2 | C2: org.openmrs.module.mdrtb | D2: UNKNOWN | F2: 1 | G2: 40505.648 | H2: 1 | I2: 2df18867-7e29-4f02-bf71-b90ff6be761c
A3: 2 | B3: 3 | C3: ZL/PIH installation in Haiti | D3: 1067 | F3: 1 | G3: 40777.626 | H3: 1 | I3: e5680f7e-7c0f-4b68-8fbc-1ce50bbd6c9b
A4: 3 | B4: 2 | C4: org.openmrs.module.mdrtb | D4: MODERATELY POSITIVE | F4: 1 | G4: 40493.439 | H4: 2 | I4: bb9b4848-0eae-4522-89fd-494a47f9639d
A5: 4 | B5: 3 | C5: ZL/PIH installation in Haiti | D5: 1408 | F5: 1 | G5: 40777.626 | H5: 2 | I5: a008e10c-3c0f-4de6-b5d7-c1e66dc90e2d
A6: 5 | B6: 3 | C6: ZL/PIH installation in Haiti | D6: 2842 | F6: 1 | G6: 40777.626 | H6: 3 | I6: ec4582ac-26d2-4f23-9417-64c829a9e8fd
A7: 6 | B7: 2 | C7: org.openmrs.module.mdrtb | D7: MULTI-DRUG RESISTANT TUBERCULOSIS CULTURE STATUS | F7: 1 | G7: 40091.942 | H7: 4 | I7: 430d97f8-0371-102d-b0e3-001ec94a0cc1
A8: 7 | B8: 3 | C8: ZL/PIH installation in Haiti | D8: 3506 | F8: 1 | G8: 40777.626 | H8: 4 | I8: e64fa862-579b-43a2-98d4-696510dc9fae
A9: 8 | B9: 3 | C9: ZL/PIH installation in Haiti | D9: 1107 | F9: 1 | G9: 40777.626 | H9: 5 | I9: 8d2e72e7-02e6-4bb2-8573-9972263c90f6
A10: 9 | B10: 2 | C10: org.openmrs.module.mdrtb | D10: NONE | F10: 1 | G10: 40091.942 | H10: 5 | I10: 430dd060-0371-102d-b0e3-001ec94a0cc1
A11: 10 | B11: 3 | C11: ZL/PIH installation in Haiti | D11: 3503 | F11: 1 | G11: 40777.626 | H11: 6 | I11: 74d2812f-f1bd-48c2-966c-e8282a8fc3fc
A12: 11 | B12: 3 | C12: ZL/PIH installation in Haiti | D12: 3504 | F12: 1 | G12: 40777.626 | H12: 7 | I12: 3a52754e-268c-48c2-8e49-7883e00081cc
A13: 12 | B13: 3 | C13: ZL/PIH installation in Haiti | D13: 3505 | F13: 1 | G13: 40777.626 | H13: 8 | I13: 384227b4-7ff9-4e82-b4ce-90ca6fe5bea5
A14: 13 | B14: 3 | C14: ZL/PIH installation in Haiti | D14: 1664 | F14: 1 | G14: 40777.626 | H14: 9 | I14: 6f87525c-8fdb-4929-84e9-5f5226696b4a
A15: 14 | B15: 2 | C15: org.openmrs.module.mdrtb | D15: AMBULATORY | F15: 1 | G15: 40493.546 | H15: 9 | I15: faeff01e-7242-4911-a20e-3f034d33e189
A16: 15 | B16: 4 | C16: PIH | D16: NO | F16: 1 | G16: 40746.575 | H16: 10 | I16: aefacf53-8e8e-4ed0-9d32-cbd1d14c6639
A17: 16 | B17: 3 | C17: ZL/PIH installation in Haiti | D17: 1066 | F17: 1 | G17: 40777.626 | H17: 10 | I17: bdfc7c88-f40c-4fe5-8937-16780212f1b9
A18: 17 | B18: 4 | C18: PIH | D18: 1066 | F18: 1 | G18: 40505.427 | H18: 10 | I18: b20d12bc-4864-102e-96e9-000c29c2a5d7
A19: 18 | B19: 3 | C19: ZL/PIH installation in Haiti | D19: 1065 | F19: 1 | G19: 40777.626 | H19: 11 | I19: 80869756-223c-4438-8ef2-6c19cd31d65a
A20: 19 | B20: 4 | C20: PIH | D20: YES | F20: 1 | G20: 40506.535 | H20: 11 | I20: 7568887a-4943-102e-96e9-000c29c2a5d7
A21: 20 | B21: 4 | C21: PIH | D21: 1065 | F21: 1 | G21: 40505.427 | H21: 11 | I21: b20d114a-4864-102e-96e9-000c29c2a5d7
A22: 21 | B22: 3 | C22: ZL/PIH installation in Haiti | D22: 3389 | F22: 1 | G22: 40777.626 | H22: 12 | I22: f12fa15a-9edc-4115-b1b5-8208b914822b
A23: 22 | B23: 2 | C23: org.openmrs.module.mdrtb | D23: HOSPITALIZED | F23: 1 | G23: 40493.546 | H23: 12 | I23: fb9c3125-3df3-4be3-a8da-750668e082c0
A24: 23 | B24: 2 | C24: org.openmrs.module.mdrtb | D24: HOSPITALIZATION WORKFLOW | F24: 1 | G24: 40493.546 | H24: 13 | I24: 8e1bacc0-43af-458c-862b-2cd19c27c6d8
A25: 24 | B25: 3 | C25: ZL/PIH installation in Haiti | D25: 6416 | F25: 1 | G25: 40777.626 | H25: 13 | I25: aad06540-1d30-4fc4-89ea-f3ae8964ae84
A26: 25 | B26: 3 | C26: ZL/PIH installation in Haiti | D26: 1743 | F26: 1 | G26: 40777.626 | H26: 14 | I26: 158d0390-25d0-4199-bd60-78312060259b
A27: 26 | B27: 2 | C27: org.openmrs.module.mdrtb | D27: DEFAULT AFTER REGIMEN 1 | F27: 1 | G27: 40506.429 | H27: 14 | I27: 0a2a8ff2-3aeb-4c7e-980d-fb1ffc80ffcc
A28: 27 | B28: 3 | C28: ZL/PIH installation in Haiti | D28: 6420 | F28: 1 | G28: 40777.626 | H28: 15 | I28: 985a3557-bcff-43a5-9407-5d42c980bc78
A29: 28 | B29: 2 | C29: org.openmrs.module.mdrtb | D29: TRANSFER | F29: 1 | G29: 40513.683 | H29: 15 | I29: 6c11850d-1dd4-45ea-917a-7bb2eb2ff101
A30: 29 | B30: 2 | C30: org.openmrs.module.mdrtb | D30: AFTER FAILURE REGIMEN 2 | F30: 1 | G30: 40091.942 | H30: 16 | I30: 430f8a0e-0371-102d-b0e3-001ec94a0cc1
A31: 30 | B31: 3 | C31: ZL/PIH installation in Haiti | D31: 1509 | F31: 1 | G31: 40777.626 | H31: 16 | I31: a73e18b5-c4cb-474f-8fcd-b9c68c40f4a7
A32: 31 | B32: 2 | C32: org.openmrs.module.mdrtb | D32: AFTER FAILURE REGIMEN 1 | F32: 1 | G32: 40091.942 | H32: 17 | I32: 430f80e0-0371-102d-b0e3-001ec94a0cc1
A33: 32 | B33: 3 | C33: ZL/PIH installation in Haiti | D33: 1526 | F33: 1 | G33: 40777.626 | H33: 17 | I33: 80e3acf0-d867-44ee-984a-3026f62c87ba
A34: 33 | B34: 2 | C34: org.openmrs.module.mdrtb | D34: NEW | F34: 1 | G34: 40513.683 | H34: 18 | I34: fe1b50aa-314b-4202-b787-95fa9ef461e6
A35: 34 | B35: 3 | C35: ZL/PIH installation in Haiti | D35: 6419 | F35: 1 | G35: 40777.626 | H35: 18 | I35: 6281812a-e410-4478-8032-d93b1b5c84b5
A36: 35 | B36: 4 | C36: PIH | D36: 5622 | F36: 1 | G36: 40505.427 | H36: 19 | I36: b299b5b4-4864-102e-96e9-000c29c2a5d7
A37: 36 | B37: 4 | C37: PIH | D37: OTHER NON-CODED | F37: 1 | G37: 40506.535 | H37: 19 | I37: 75aa9616-4943-102e-96e9-000c29c2a5d7
A38: 37 | B38: 3 | C38: ZL/PIH installation in Haiti | D38: 5622 | F38: 1 | G38: 40777.626 | H38: 19 | I38: a653fa39-f123-454d-862b-c5b08e4c721b
A39: 38 | B39: 2 | C39: org.openmrs.module.mdrtb | D39: RELAPSE AFTER REGIMEN 1 | F39: 1 | G39: 40513.683 | H39: 20 | I39: 86c09c7d-eac8-43f9-9699-d341f8a79b6d
A40: 39 | B40: 3 | C40: ZL/PIH installation in Haiti | D40: 6349 | F40: 1 | G40: 40777.626 | H40: 20 | I40: 3e2a1aa4-f218-4abd-a254-52b78e81eb36
...

Sheet concept_name
A1: concept_id | B1: name | C1: locale | D1: type | E1: concept_uuid
A2: 1 | B2: UNKNOWN | C2: en | D2: FULLY_SPECIFIED | E2: =VLOOKUP(A2,concept!A:K, 11) -> 31b2810e-0370-102d-b0e3-001ec94a0cc1
A3: 1 | B3: Данных нет | C3: ru | D3: FULLY_SPECIFIED | E3: =VLOOKUP(A3,concept!A:K, 11) -> 31b2810e-0370-102d-b0e3-001ec94a0cc1
A4: 1 | B4: Маълумот нест | C4: tj | D4: FULLY_SPECIFIED | E4: =VLOOKUP(A4,concept!A:K, 11) -> 31b2810e-0370-102d-b0e3-001ec94a0cc1
A5: 2 | B5: ++ | C5: en | D5: SHORT | E5: =VLOOKUP(A5,concept!A:K, 11) -> 31b4a16e-0370-102d-b0e3-001ec94a0cc1
A6: 2 | B6: ++ | C6: ru | D6: SHORT | E6: =VLOOKUP(A6,concept!A:K, 11) -> 31b4a16e-0370-102d-b0e3-001ec94a0cc1
A7: 2 | B7: ++ | C7: tj | D7: SHORT | E7: =VLOOKUP(A7,concept!A:K, 11) -> 31b4a16e-0370-102d-b0e3-001ec94a0cc1
A8: 2 | B8: MODERATELY POSITIVE | C8: en | D8: FULLY_SPECIFIED | E8: =VLOOKUP(A8,concept!A:K, 11) -> 31b4a16e-0370-102d-b0e3-001ec94a0cc1
A9: 2 | B9: Умеренно положительный | C9: ru | D9: FULLY_SPECIFIED | E9: =VLOOKUP(A9,concept!A:K, 11) -> 31b4a16e-0370-102d-b0e3-001ec94a0cc1
A10: 2 | B10: Мусбати мӯътадил | C10: tj | D10: FULLY_SPECIFIED | E10: =VLOOKUP(A10,concept!A:K, 11) -> 31b4a16e-0370-102d-b0e3-001ec94a0cc1
A11: 3 | B11: MDR-TB PROGRAM | C11: en | D11: FULLY_SPECIFIED | E11: =VLOOKUP(A11,concept!A:K, 11) -> 31bd79ec-0370-102d-b0e3-001ec94a0cc1
A12: 3 | B12: Программа МЛУ-ТБ | C12: ru | D12: FULLY_SPECIFIED | E12: =VLOOKUP(A12,concept!A:K, 11) -> 31bd79ec-0370-102d-b0e3-001ec94a0cc1
A13: 3 | B13: Барномаҳои ШУС | C13: tj | D13: FULLY_SPECIFIED | E13: =VLOOKUP(A13,concept!A:K, 11) -> 31bd79ec-0370-102d-b0e3-001ec94a0cc1
... A33: 10 | B33: NO | C33: en | D33: FULLY_SPECIFIED | E33: =VLOOKUP(A33,concept!A:K, 11) -> 31b2803c-0370-102d-b0e3-001ec94a0cc1
A34: 10 | B34: FALSE | C34: en | D34: SHORT | E34: =VLOOKUP(A34,concept!A:K, 11) -> 31b2803c-0370-102d-b0e3-001ec94a0cc1
A35: 10 | B35: Нет | C35: ru | D35: SHORT | E35: =VLOOKUP(A35,concept!A:K, 11) -> 31b2803c-0370-102d-b0e3-001ec94a0cc1
A36: 10 | B36: Ложь | C36: tj | D36: SHORT | E36: =VLOOKUP(A36,concept!A:K, 11) -> 31b2803c-0370-102d-b0e3-001ec94a0cc1
A37: 10 | B37: Нет | C37: ru | D37: FULLY_SPECIFIED | E37: =VLOOKUP(A37,concept!A:K, 11) -> 31b2803c-0370-102d-b0e3-001ec94a0cc1
A38: 10 | B38: Не | C38: tj | D38: FULLY_SPECIFIED | E38: =VLOOKUP(A38,concept!A:K, 11) -> 31b2803c-0370-102d-b0e3-001ec94a0cc1
A39: 11 | B39: YES | C39: en | D39: FULLY_SPECIFIED | E39: =VLOOKUP(A39,concept!A:K, 11) -> 31b27f6a-0370-102d-b0e3-001ec94a0cc1
A40: 11 | B40: TRUE | C40: en | D40: SHORT | E40: =VLOOKUP(A40,concept!A:K, 11) -> 31b27f6a-0370-102d-b0e3-001ec94a0cc1
A41: 11 | B41: Да | C41: ru | D41: SHORT | E41: =VLOOKUP(A41,concept!A:K, 11) -> 31b27f6a-0370-102d-b0e3-001ec94a0cc1
A42: 11 | B42: Истина | C42: tj | D42: SHORT | E42: =VLOOKUP(A42,concept!A:K, 11) -> 31b27f6a-0370-102d-b0e3-001ec94a0cc1
A43: 11 | B43: Да | C43: ru | D43: FULLY_SPECIFIED | E43: =VLOOKUP(A43,concept!A:K, 11) -> 31b27f6a-0370-102d-b0e3-001ec94a0cc1
A44: 11 | B44: Ња | C44: tj | D44: FULLY_SPECIFIED | E44: =VLOOKUP(A44,concept!A:K, 11) -> 31b27f6a-0370-102d-b0e3-001ec94a0cc1
A45: 12 | B45: PATIENT HOSPITALIZED | C45: en | D45: FULLY_SPECIFIED | E45: =VLOOKUP(A45,concept!A:K, 11) -> 31c095fa-0370-102d-b0e3-001ec94a0cc1
A46: 12 | B46: Пациент госпитализирован | C46: ru | D46: FULLY_SPECIFIED | E46: =VLOOKUP(A46,concept!A:K, 11) -> 31c095fa-0370-102d-b0e3-001ec94a0cc1
A47: 12 | B47: Бемор дар беморхона бистарӣ мешавад | C47: tj | D47: FULLY_SPECIFIED | E47: =VLOOKUP(A47,concept!A:K, 11) -> 31c095fa-0370-102d-b0e3-001ec94a0cc1
A48: 13 | B48: HOSPITALIZATION | C48: en | D48: SHORT | E48: =VLOOKUP(A48,concept!A:K, 11) -> d3d3e1a7-7230-4085-af56-690977a479e5
A49: 13 | B49: ГОСПИТАЛИЗАЦИЯ | C49: ru | D49: SHORT | E49: =VLOOKUP(A49,concept!A:K, 11) -> d3d3e1a7-7230-4085-af56-690977a479e5
A50: 13 | B50: ГОСПИТАЛИЗАЦИЯ | C50: tj | D50: SHORT | E50: =VLOOKUP(A50,concept!A:K, 11) -> d3d3e1a7-7230-4085-af56-690977a479e5
A51: 13 | B51: HOSPITALIZATION WORKFLOW | C51: en | D51: FULLY_SPECIFIED | E51: =VLOOKUP(A51,concept!A:K, 11) -> d3d3e1a7-7230-4085-af56-690977a479e5
A52: 13 | B52: Статус госпитализации | C52: ru | D52: FULLY_SPECIFIED | E52: =VLOOKUP(A52,concept!A:K, 11) -> d3d3e1a7-7230-4085-af56-690977a479e5
... A2951: 843 | B2951: РУ-Сил | C2951: tj | D2951: FULLY_SPECIFIED | E2951: =VLOOKUP(A2951,concept!A:K, 11) -> 06632992-b049-40c0-a324-2cbd6b5ab23b

Sheet concept_set
A1: concept_set_id | B1: concept_id | C1: concept_set | D1: sort_weight | E1: creator | F1: date_created | G1: uuid
A2: 1 | B2: 9 | C2: 13 | D2: 1 | E2: 1 | F2: 40527.492 | G2: f9a3f96e-e0a6-4434-b611-9161d3b37014
A3: 2 | B3: 12 | C3: 13 | D3: 0 | E3: 1 | F3: 40527.492 | G3: a2546c56-a455-466c-a7ad-72e2edfb74f7
A4: 187 | B4: 324 | C4: 13 | D4: 2 | E4: 1 | F4: 42379.571 | G4: 7fa608e7-566c-4c97-9cce-1ca9e1626ea3
A5: 3 | B5: 22 | C5: 30 | D5: 6 | E5: 1 | F5: 40679.597 | G5: 2c020997-af91-411f-9512-bcd86d1dcb78
A6: 4 | B6: 23 | C6: 30 | D6: 3 | E6: 1 | F6: 40527.484 | G6: c4a1cdb2-a1fc-4718-86be-4bcffcb4ff01
A7: 5 | B7: 25 | C7: 30 | D7: 1 | E7: 1 | F7: 40527.484 | G7: 674c784f-e80e-4a3b-a656-b6ee8f6f6420
A8: 6 | B8: 26 | C8: 30 | D8: 0 | E8: 1 | F8: 40527.484 | G8: 2d3126ef-22fb-4f2a-a1b5-66ef159495e4
A9: 7 | B9: 27 | C9: 30 | D9: 4 | E9: 1 | F9: 40527.485 | G9: cf80df00-8578-41b1-b92b-68f7b435d316
A10: 8 | B10: 28 | C10: 30 | D10: 2 | E10: 1 | F10: 40527.484 | G10: f9d81340-888b-4f82-a7b0-b19be493b754
A11: 9 | B11: 29 | C11: 30 | D11: 5 | E11: 1 | F11: 40679.595 | G11: 7750cc2b-0e3b-48ca-8d0f-b8b9fc957782
A12: 10 | B12: 43 | C12: 69 | D12: 2 | E12: 1 | F12: 39889.672 | G12: 325a7454-0370-102d-b0e3-001ec94a0cc1
A13: 11 | B13: 45 | C13: 69 | D13: 5 | E13: 1 | F13: 39889.672 | G13: 325a73a0-0370-102d-b0e3-001ec94a0cc1
... A272: 271 | B272: 307 | C272: 789 | D272: 13 | E272: 1 | F272: 46149.501 | G272: c254459c-49e2-11f1-a20f-10ffe00bc20f

Sheet concept_answer
A1: concept_answer_id | B1: concept_id | C1: answer_concept | D1: date_created | E1: sort_weight | F1: uuid
A2: 1 | B2: 12 | C2: 10 | D2: 39889.672 | E2: 1 | F2: 31ea73f2-0370-102d-b0e3-001ec94a0cc1
A3: 2 | B3: 12 | C3: 11 | D3: 39889.672 | E3: 1 | F3: 31ea74a6-0370-102d-b0e3-001ec94a0cc1
A4: 291 | B4: 21 | C4: 14 | D4: 42379.751 | E4: 1 | F4: 76d8c72a-ede8-47ef-8fcc-6cce6ebf8d8e
A5: 4 | B5: 21 | C5: 15 | D5: 40527.482 | E5: 1 | F5: 7b04eb2f-8983-415a-a2b1-1adab4ee6515
A6: 5 | B6: 21 | C6: 16 | D6: 39889.672 | E6: 1 | F6: 31e7de76-0370-102d-b0e3-001ec94a0cc1
A7: 6 | B7: 21 | C7: 17 | D7: 39889.672 | E7: 1 | F7: 31e7dbba-0370-102d-b0e3-001ec94a0cc1
A8: 7 | B8: 21 | C8: 18 | D8: 40527.482 | E8: 1 | F8: 7a60b6f6-f9d6-4250-8622-3ddbd7bbe21f
A9: 8 | B9: 21 | C9: 19 | D9: 40527.482 | E9: 1 | F9: f9140065-297a-46d7-8689-481c5fe3a321
A10: 9 | B10: 21 | C10: 20 | D10: 40527.482 | E10: 1 | F10: e07dee1c-25d2-44d0-a4b7-86183dfa48c9
A11: 466 | B11: 21 | C11: 430 | D11: 42580.478 | E11: 1 | F11: 11276ec7-c382-49fd-ae62-d77c92786ef1
A12: 467 | B12: 21 | C12: 431 | D12: 42580.478 | E12: 1 | F12: 62419e53-d8d7-44f1-8410-c83377cb1e26
A13: 474 | B13: 30 | C13: 22 | D13: 42580.48 | E13: 1 | F13: e988cc53-a8db-4fe0-9d9d-9952f0b6cd8d
... A912: 944 | B912: 435 | C912: 843 | D912: 46310.994 | E912: 1 | F912: 46fcad82-3259-48e3-8de8-a1a4de46276f
